Workbook

Sheet FILL IN
B1: Input the percentage for each name or flat percentage split for general/specific names
B3: Lagos | G3: East | L3: WEST | Q3: Middle Belt | V3: North | AA3: Modern Trade | AF3: Benin
B4: General names | C4: % | D4: Specific | E4: % | G4: General names | H4: % | I4: Specific | J4: % | L4: General names | M4: % | N4: Specific | O4: % | Q4: General names | R4: % | S4: Specific | T4: % | V4: General names | X4: Specific | Y4: % | AA4: General names | AB4: % | AC4: Specific | AD4: % | AF4: General names | AG4: % | AH4: Specific | AI4: %
B5: Mummy | D5: Tomi | G5: Mummy | I5: Nnenna | L5: Mummy | N5: Tomi | Q5: Mummy | S5: Aisha | V5: Mummy | X5: Aisha | AA5: Mummy | AC5: Aisha | AF5: Mummy | AH5: Aisha
B6: Aunty | D6: Toyin | G6: Aunty | I6: Sister | L6: Aunty | N6: Toyin | Q6: Aunty | S6: Halima | V6: Aunty | X6: Halima | AA6: Aunty | AC6: Halima | AF6: Aunty | AH6: Halima
B7: Bestie | D7: Tolu | G7: Bestie | I7: Chichi | L7: Bestie | N7: Tolu | Q7: Bestie | S7: Fatima | V7: Bestie | X7: Fatima | AA7: Bestie | AC7: Fatima | AF7: Bestie | AH7: Fatima
B8: Babe | D8: Ope | G8: Babe | I8: Ngozi | L8: Babe | N8: Ope | Q8: Babe | S8: Zainab | V8: Babe | X8: Zainab | AA8: Babe | AC8: Zainab | AF8: Babe | AH8: Zainab
B9: Beauty | D9: Kemi | G9: Beauty | I9: Ada | L9: Beauty | N9: Kemi | Q9: Beauty | S9: Ummi | V9: Beauty | X9: Ummi | AA9: Beauty | AC9: Ummi | AF9: Beauty | AH9: Ummi
B10: Wifey | D10: Bisi | G10: Wifey | I10: Uche | L10: Wifey | N10: Bisi | Q10: Wifey | S10: Hajiya | V10: Wifey | X10: Hajiya | AA10: Wifey | AC10: Hajiya | AF10: Wifey | AH10: Hajiya
B11: Blessing | D11: Shade | G11: Blessing | I11: Ify | L11: Blessing | N11: Shade | Q11: Blessing | S11: Amina | V11: Blessing | X11: Amina | AA11: Blessing | AC11: Amina | AF11: Blessing | AH11: Amina
B12: Cynthia | D12: Yetunde | G12: Cynthia | I12: Oge | L12: Cynthia | N12: Yetunde | Q12: Cynthia | S12: Nana | V12: Cynthia | X12: Nana | AA12: Cynthia | AC12: Nana | AF12: Cynthia | AH12: Nana
B13: Mary | D13: Yemi | G13: Mary | I13: Amaka | L13: Mary | N13: Yemi | Q13: Mary | S13: Gwaggo | V13: Mary | X13: Gwaggo | AA13: Mary | AC13: Gwaggo | AF13: Mary | AH13: Gwaggo
B14: Darling | D14: Titi | G14: Darling | I14: Nkechi | L14: Darling | N14: Titi | Q14: Darling | S14: Mariam | V14: Darling | X14: Mariam | AA14: Darling | AC14: Mariam | AF14: Darling | AH14: Mariam
B15: Fine Girl | D15: Lola | G15: Fine Girl | I15: Oluchi | L15: Fine Girl | N15: Lola | Q15: Fine Girl | S15: Hauwa | V15: Fine Girl | X15: Hauwa | AA15: Fine Girl | AC15: Hauwa | AF15: Fine Girl | AH15: Hauwa
B16: Lizzy | D16: Tayo | G16: Lizzy | I16: Nkem | L16: Lizzy | N16: Tayo | Q16: Lizzy | S16: Hajara | V16: Lizzy | X16: Hajara | AA16: Lizzy | AC16: Hajara | AF16: Lizzy | AH16: Hajara
... B25: Jessica | D25: Tutu | G25: Jessica | I25: Zuby | L25: Jessica | N25: Tutu | Q25: Jessica | S25: Fauzia | V25: Jessica | X25: Fauzia | AA25: Jessica | AC25: Fauzia | AF25: Jessica | AH25: Fauzia
B26: Grace | D26: Bola | G26: Grace | I26: Amara | L26: Grace | N26: Bola | Q26: Grace | V26: Grace | AA26: Grace | AC26: Ose | AF26: Grace | AH26: Ose
B27: Ivy | D27: Kike | G27: Ivy | I27: Oby | L27: Ivy | N27: Kike | Q27: Ivy | V27: Ivy | AA27: Ivy | AC27: Ehi | AF27: Ivy | AH27: Ehi
B28: Mary | D28: Folake | G28: Mary | I28: Sochi | L28: Mary | N28: Folake | Q28: Mary | V28: Mary | AA28: Mary | AC28: Ekaette | AF28: Mary | AH28: Ekaette
B29: Rachael | D29: Funmi | G29: Rachael | I29: Sommy | L29: Rachael | N29: Funmi | Q29: Rachael | V29: Rachael | AA29: Rachael | AC29: Mfon | AF29: Rachael | AH29: Mfon
B30: Vicky | D30: Seun | G30: Vicky | I30: Nwannem | L30: Vicky | N30: Seun | Q30: Vicky | V30: Vicky | AA30: Vicky | AC30: Uduak | AF30: Vicky | AH30: Uduak
B31: Anita | D31: Kehinde | G31: Anita | I31: Nneoma | L31: Anita | N31: Kehinde | Q31: Anita | V31: Anita | AA31: Anita | AC31: Idara | AF31: Anita | AH31: Idara
B32: Nne | D32: Taiwo | G32: Nne | I32: Enyi'm | L32: Nne | N32: Taiwo | Q32: Nne | V32: Nne | AA32: Nne | AC32: Tomi | AF32: Nne | AH32: Tomi
B33: Ada | D33: Titi | G33: Ada | I33: Nnwannem Nwanyi | L33: Ada | N33: Titi | Q33: Ada | V33: Ada | AA33: Ada | AC33: Toyin | AF33: Ada | AH33: Toyin
B34: Chioma | D34: Nike | G34: Chioma | L34: Chioma | N34: Nike | Q34: Chioma | V34: Chioma | AA34: Chioma | AC34: Tolu | AF34: Chioma | AH34: Tolu
B35: Chidinma | D35: Wunmi | G35: Chidinma | L35: Chidinma | N35: Wunmi | Q35: Chidinma | V35: Chidinma | AA35: Chidinma | AC35: Ope | AF35: Chidinma | AH35: Ope
B36: Oluchi | D36: Mayowa | G36: Oluchi | L36: Oluchi | N36: Mayowa | Q36: Oluchi | V36: Oluchi | AA36: Oluchi | AC36: Kemi | AF36: Oluchi | AH36: Kemi
B37: Uju | D37: Opeyemi | G37: Uju | L37: Uju | N37: Opeyemi | Q37: Uju | V37: Uju | AA37: Uju | AC37: Bisi | AF37: Uju | AH37: Bisi
B38: Ifeoma | D38: Ore mi | G38: Ifeoma | L38: Ifeoma | N38: Ore mi | Q38: Ifeoma | V38: Ifeoma | AA38: Ifeoma | AC38: Shade | AF38: Ifeoma | AH38: Shade
B39: Amaka | D39: Maami | G39: Amaka | L39: Amaka | N39: Maami | Q39: Amaka | V39: Amaka | AA39: Amaka | AC39: Nnenna | AF39: Amaka | AH39: Nnenna
B40: Amara | G40: Amara | L40: Amara | Q40: Amara | V40: Amara | AA40: Amara | AC40: Sister | AF40: Amara | AH40: Sister
B41: Ngozi | G41: Ngozi | L41: Ngozi | Q41: Ngozi | V41: Ngozi | AA41: Ngozi | AC41: Chichi | AF41: Ngozi | AH41: Chichi
B42: Nkiru | G42: Nkiru | L42: Nkiru | Q42: Nkiru | V42: Nkiru | AA42: Nkiru | AC42: Ngozi | AF42: Nkiru | AH42: Ngozi
B43: Nkechi | G43: Nkechi | L43: Nkechi | Q43: Nkechi | V43: Nkechi | AA43: Nkechi | AC43: Ada | AF43: Nkechi | AH43: Ada
B44: Ijeoma | G44: Ijeoma | L44: Ijeoma | Q44: Ijeoma | V44: Ijeoma | AA44: Ijeoma | AC44: Uche | AF44: Ijeoma | AH44: Uche
B45: Ezinne | G45: Ezinne | L45: Ezinne | Q45: Ezinne | V45: Ezinne | AA45: Ezinne | AC45: Ify | AF45: Ezinne | AH45: Ify
B46: Nneoma | G46: Nneoma | L46: Nneoma | Q46: Nneoma | V46: Nneoma | AA46: Nneoma | AC46: Oge | AF46: Nneoma | AH46: Oge
B47: Chidera | G47: Chidera | L47: Chidera | Q47: Chidera | V47: Chidera | AA47: Chidera | AC47: Amaka | AF47: Chidera | AH47: Amaka
B48: Yetunde | G48: Yetunde | L48: Yetunde | Q48: Yetunde | V48: Yetunde | AA48: Yetunde | AC48: Nkechi | AF48: Yetunde | AH48: Nkechi
B49: Bisola | G49: Bisola | L49: Bisola | Q49: Bisola | V49: Bisola | AA49: Bisola | AC49: Oluchi | AF49: Bisola | AH49: Oluchi
...

Sheet planning
A2: q2
B3: Year | C3: Values | S3: Wkly/Rr | Y3: Wkly/Rr | AE3: Wkly/Rr
B4: 2024/25 Tgt | D4: 2024/25 | I4: Q4 Tentative Target | J4: 19258.332 | K4: 19256.917 | L4: 24072.511 | M4: =SUM(J4:L4) -> 62587.76 | O4: LY | P4: 26990 | Q4: 30678 | R4: 35114 | S4: =AVERAGE(SUM(P4:R4)/13) -> 7137.0769 | U4: L3M | V4: 19802 | W4: 28666 | X4: 19565.408 | Y4: =AVERAGE(SUM(V4:X4)/13) -> 5233.3391 | AA4: L08 | AB4: 36554 | AC4: 36390 | AD4: 45568 | AE4: =AVERAGE(SUM(AB4:AD4)/13) -> 9116.3077
A5: Region | B5: Sum of Cs | C5: Sum of NIV | D5: Sum of Cs | E5: Sum of NIV | I5: Plus 10% Projection | J5: ='Revised Volume'!F12 -> 40628 | K5: ='Revised Volume'!G12 -> 37239 | L5: ='Revised Volume'!H12 -> 46536 | M5: =SUM(J5:L5) -> 124403 | O5: Projection | P5: =($S$4/3)*13 -> 30927.333 | Q5: =($S$4/3)*13 -> 30927.333 | R5: =($S$4/3)*13 -> 30927.333 | S5: =AVERAGE(SUM(P5:R5)/13) -> 7137.0769 | U5: Projection | V5: =($Y$4/3)*13 -> 22677.803 | W5: =($Y$4/3)*13 -> 22677.803 | X5: =($Y$4/3)*13 -> 22677.803 | Y5: =AVERAGE(SUM(V5:X5)/13) -> 5233.3391 | AA5: Projection | AB5: =($AE$4/3)*13 -> 39504 | AC5: =($AE$4/3)*13 -> 39504 | AD5: =($AE$4/3)*13 -> 39504 | AE5: =AVERAGE(SUM(AB5:AD5)/13) -> 9116.3077
A6: Region 1 (Lagos) | B6: 21990.197 | C6: 448042.54 | D6: 26246 | E6: 568743.41 | J6: P10 | K6: P11 | L6: P12 | M6: Q4 | O6: 10% Up | P6: =P5*107% -> 33092.247 | Q6: =Q5*103% -> 31855.153 | R6: =R5*120% -> 37112.8 | S6: =AVERAGE(SUM(P6:R6)/13) -> 7850.7846 | U6: 10% Up | V6: =V5*110% -> 24945.583 | W6: =W5*110% -> 24945.583 | X6: =X5*110% -> 24945.583 | Y6: =AVERAGE(SUM(V6:X6)/13) -> 5756.673 | AA6: 10% Up | AB6: =AB5*110% -> 43454.4 | AC6: =AC5*110% -> 43454.4 | AD6: =AD5*110% -> 43454.4 | AE6: =AVERAGE(SUM(AB6:AD6)/13) -> 10027.938
A7: Region 2 (West) | B7: 12362.838 | C7: 251888.47 | D7: 17804 | E7: 383868.73 | H7: Region 1 (Lagos) | I7: =D6/$D$12 -> 0.26263334 | J7: =I7*$J$5 -> 10670.267 | K7: =$K$5*I7 -> 9780.2029 | L7: =$L$5*I7 -> 12221.905 | M7: =SUM(J7:L7) -> 32672.375 | O7: Growth vs PY | P7: =P6-P4 -> 6102.2467 | Q7: =Q6-Q4 -> 1177.1533 | R7: =R6-R4 -> 1998.8 | U7: Growth vs L3M | V7: =V6-V4 -> 5143.5829 | W7: =W6-W4 -> -3720.4171 | X7: =X6-X4 -> 5380.1749 | AA7: Growth vs L08 | AB7: =AB6-AB4 -> 6900.4 | AC7: =AC6-AC4 -> 7064.4 | AD7: =AD6-AD4 -> -2113.6
A8: Region 3 (East) | B8: 14652.267 | C8: 298563.79 | D8: 14778 | E8: 317639.41 | H8: Region 2 (West- Benin Exclusive) | I8: =D7/$D$12 -> 0.17815758 | J8: =I8*$J$5 -> 7238.1863 | K8: =$K$5*I8 -> 6634.4103 | L8: =$L$5*I8 -> 8290.7413 | M8: =SUM(J8:L8)-M9 -> 14184.536 | O8: % Growth | P8: =(P6/P4)-1 -> 0.22609287 | Q8: =(Q6/Q4)-1 -> 0.038371254 | R8: =(R6/R4)-1 -> 0.056923165 | S8: =(S6/S4)-1 -> 0.1 | U8: % Growth | V8: =(V6/V4)-1 -> 0.25975068 | W8: =(W6/W4)-1 -> -0.12978501 | X8: =(X6/X4)-1 -> 0.27498404 | Y8: =(Y6/Y4)-1 -> 0.1 | AA8: % Growth | AB8: =(AB6/AB4)-1 -> 0.18877277 | AC8: =(AC6/AC4)-1 -> 0.19413026 | AD8: =(AD6/AD4)-1 -> -0.046383427 | AE8: =(AE6/AE4)-1 -> 0.1
A9: Region 4 (North) | B9: 8556.0582 | C9: 174326.67 | D9: 8383 | E9: 182710.48 | H9: Benin (36% Contr. To West) | I9: 0.36 | J9: =J8*36% -> 2605.7471 | K9: =K8*36% -> 2388.3877 | L9: =L8*36% -> 2984.6669 | M9: =SUM(J9:L9) -> 7978.8017
A10: Region 5 (Mid-Belt) | B10: 16928.145 | C10: 344905.52 | D10: 17388 | E10: 374798.66 | H10: Region 3 (East) | I10: =D8/$D$12 -> 0.1478776 | J10: =I10*$J$5 -> 6007.9711 | K10: =$K$5*I10 -> 5506.8139 | L10: =$L$5*I10 -> 6881.632 | M10: =SUM(J10:L10) -> 18396.417 | AB10: 0.85 | AC10: 0.85 | AD10: 0.85
A11: Region 6 (Modern Trade) | B11: 12388.514 | C11: 252411.52 | D11: 15335 | E11: 347478.84 | H11: Region 4 (North) | I11: =D9/$D$12 -> 0.083885364 | J11: =I11*$J$5 -> 3408.0946 | K11: =$K$5*I11 -> 3123.8071 | L11: =$L$5*I11 -> 3903.6893 | M11: =SUM(J11:L11) -> 10435.591 | O11: MF In-pack financials | U11: Vol | V11: P10 | W11: P11 | X11: P12 | Y11: Wkly/Rr | AB11: =AB10*AB4 -> 31070.9 | AC11: =AC10*AC4 -> 30931.5 | AD11: =AD10*AD4 -> 38732.8
A12: Grand Total | B12: 86878.021 | C12: 1770138.5 | D12: 99934 | E12: 2175239.5 | H12: Region 5 (Mid-Belt) | I12: =D10/$D$12 -> 0.17399484 | J12: =I12*$J$5 -> 7069.0622 | K12: =$K$5*I12 -> 6479.3937 | L12: =$L$5*I12 -> 8097.0237 | M12: =SUM(J12:L12) -> 21645.48 | T12: L08 | U12: =SUM(V12:X12) -> 100735.2 | V12: =AB11 -> 31070.9 | W12: =AC11 -> 30931.5 | X12: =AD11 -> 38732.8 | Y12: =AVERAGE(SUM(V12:X12)/13) -> 7748.8615 | AB12: =AB4-AB11 -> 5483.1 | AC12: =AC4-AC11 -> 5458.5 | AD12: =AD4-AD11 -> 6835.2
H13: Region 6 (Modern Trade) | I13: =D11/$D$12 -> 0.15345128 | J13: =I13*$J$5 -> 6234.4185 | K13: =$K$5*I13 -> 5714.3721 | L13: =$L$5*I13 -> 7141.0087 | M13: =SUM(J13:L13) -> 19089.799 | T13: Revised Volume | U13: =SUM(V13:X13) -> 92782 | V13: 26990 | W13: 30678 | X13: 35114 | Y13: =AVERAGE(SUM(V13:X13)/13) -> 7137.0769 | AB13: =AB12/AB4 -> 0.15 | AC13: =AC12/AC4 -> 0.15 | AD13: =AD12/AD4 -> 0.15
I14: =D12/$D$12 -> 1 | J14: =I14*$J$5 -> 40628 | K14: =$K$5*I14 -> 37239 | L14: =$L$5*I14 -> 46536 | M14: =SUM(J14:L14) -> 124403 | O14: Action Plan | P14: Trade execution | T14: Uplift vs L08 | U14: =U13-U12 -> -7953.2 | V14: =V13-V12 -> -4080.9 | W14: =W13-W12 -> -253.5 | X14: =X13-X12 -> -3618.8 | Y14: =Y13-Y12 -> -611.78462
P15: Mix and Merge | T15: % Uplift | U15: =(U13/U12)-1 -> -0.078951548 | V15: =V13/V12-1 -> -0.13134154 | W15: =W13/W12-1 -> -0.0081955288 | X15: =X13/X12-1 -> -0.093429858 | Y15: =Y13/Y12-1 -> -0.078951548
P16: Design a plan to deliver volume
B17: 14564.826 | C17: 14564.84 | D17: 18206.163
P18: In-pack | T18: To match up with PY number without incremental, Uplift for Q4 vs LY is 5%, growth vs LY is nil
P19: Name Customisation | T19: Accelerate run rate by 36% vs L3M
P20: In-store Activation (similar to P07) | T20: Share with Ego with Chdinma in coopy
P21: In-stor Branding for IWD | T21: Update Volume split for the names
T22: Testing the Case with Aramide (Mf 200mls to 1ltr)
T23: Identifying value to shoppers; Lucky dip? Chris to check store inventory; New Promo items idea
T24: POS awareness
T25: Speak to Maggie for a code for the MF 1Ltr for the In-pack
Y29: ='Revised Volume'!M5/'Revised Volume'!M4 -> 0.74581803
T36: rev

Sheet Revised Volume
E1: Total MF 1Ltr Volume | M1: Breadown by Variant
E3: Q4 Vol | F3: P10 | G3: P11 | H3: P12 | I3: Wkly/Rr | M3: Q4 Vol | N3: P10 | O3: P11 | P3: P12 | Q3: Wkly/Rr
D4: LY | E4: =SUM(F4:H4) -> 124403 | F4: 40628 | G4: 37239 | H4: 46536 | I4: =AVERAGE(SUM(F4:H4)/13) -> 9569.4615 | L4: LY | M4: =SUM(N4:P4) -> 124403 | N4: =F4 -> 40628 | O4: =G4 -> 37239 | P4: =H4 -> 46536 | Q4: =AVERAGE(SUM(N4:P4)/13) -> 9569.4615
D5: L08 | E5: =SUM(F5:H5) -> 118512 | F5: 36554 | G5: 36390 | H5: 45568 | I5: =AVERAGE(SUM(F5:H5)/13) -> 9116.3077 | L5: 1Ltr Original | M5: =SUM(N5:P5) -> 92782 | N5: 26990 | O5: 30678 | P5: 35114 | Q5: =AVERAGE(SUM(N5:P5)/13) -> 7137.0769
D6: Revised Volume | E6: =SUM(F6:H6) -> 124403 | F6: =F4 -> 40628 | G6: =G4 -> 37239 | H6: =H4 -> 46536 | I6: =AVERAGE(SUM(F6:H6)/13) -> 9569.4615 | L6: 1Ltr Zesty | M6: =SUM(N6:P6) -> 31621 | N6: 13638 | O6: 6561 | P6: 11422 | Q6: =AVERAGE(SUM(N6:P6)/13) -> 2432.3846
D7: Uplift | E7: =E6-E5 -> 5891 | F7: =F6-F5 -> 4074 | G7: =G6-G5 -> 849 | H7: =H6-H5 -> 968 | I7: =I6-I5 -> 453.15385
D8: % Uplift | E8: =(E6/E5)-1 -> 0.049708046 | F8: =F6/F5-1 -> 0.11145155 | G8: =G6/G5-1 -> 0.023330585 | H8: =H6/H5-1 -> 0.021242978 | I8: =I6/I5-1 -> 0.049708046 | L8: L08 | M8: =SUM(N8:P8) -> 118512 | N8: =F5 -> 36554 | O8: =G5 -> 36390 | P8: =H5 -> 45568 | Q8: =AVERAGE(SUM(N8:P8)/13) -> 9116.3077
L9: 1Ltr Original | M9: =SUM(N9:P9) -> 100735.2 | N9: =N8*85% -> 31070.9 | O9: =O8*85% -> 30931.5 | P9: =P8*85% -> 38732.8 | Q9: =AVERAGE(SUM(N9:P9)/13) -> 7748.8615
I10: Wkly/Rr | L10: 1Ltr Zesty | M10: =SUM(N10:P10) -> 17776.8 | N10: =N8*15% -> 5483.1 | O10: =O8*15% -> 5458.5 | P10: =P8*15% -> 6835.2 | Q10: =AVERAGE(SUM(N10:P10)/13) -> 1367.4462
D11: L3M | E11: =SUM(F11:H11) -> 96730.227 | F11: 29127 | G11: 41155 | H11: 26448.227 | I11: =AVERAGE(SUM(F11:H11)/13) -> 7440.7867
D12: Revised Volume | E12: =SUM(F12:H12) -> 124403 | F12: =F6 -> 40628 | G12: =G6 -> 37239 | H12: =H6 -> 46536 | I12: =AVERAGE(SUM(F12:H12)/13) -> 9569.4615 | L12: Revised Volume | M12: =SUM(N12:P12) -> 124403 | N12: =F12 -> 40628 | O12: =G12 -> 37239 | P12: =H12 -> 46536 | Q12: =AVERAGE(SUM(N12:P12)/13) -> 9569.4615
D13: Growth vs L3M | E13: =E12/E11-1 -> 0.28608196 | F13: =F12/F11-1 -> 0.39485701 | G13: =G12/G11-1 -> -0.095152472 | H13: =H12/H11-1 -> 0.75951303 | I13: =I12/I11-1 -> 0.28608196 | K13: 0.85 | L13: 1Ltr Original | N13: =N12*$K$13 -> 34533.8 | O13: =O12*$K$13 -> 31653.15 | P13: =P12*$K$13 -> 39555.6 | Q13: =AVERAGE(SUM(N13:P13)/13) -> 8134.0423
K14: 0.15 | L14: 1Ltr Zesty | M14: =SUM(N14:P14) -> 18660.45 | N14: =N12*$K$14 -> 6094.2 | O14: =O12*$K$14 -> 5585.85 | P14: =P12*$K$14 -> 6980.4 | Q14: =AVERAGE(SUM(N14:P14)/13) -> 1435.4192
D16: Comment | E16: To match up with LY number for Total MF 1Ltr without incremental. Uplift for Q4 vs L08 is 5%, growth vs LY is nil; Growth vs L3M is 29% | L16: Comment

Sheet Name SPLIT
B1: Lagos Total Volume | G1: ='By Region'!M6 -> 32672.375 | I1: East Total Volume | N1: ='By Region'!M9 -> 18396.417 | P1: West Total Volume | U1: ='By Region'!M7 -> 14184.536 | W1: MB Total Volume | AB1: ='By Region'!M11 -> 21645.48 | AD1: North Total Volume | AI1: ='By Region'!M10 -> 10435.591 | AK1: MT Total Volume | AP1: ='By Region'!M12 -> 19089.799 | AR1: Benin Total Volume | AW1: ='By Region'!M8 -> 7978.8017
B2: Lagos | I2: East | P2: WEST | W2: Middle Belt | AD2: North | AK2: Modern Trade | AR2: Benin
B3: General names | C3: 0.4 | D3: =G1*C3 -> 13068.95 | E3: Specific | F3: 0.6 | G3: =G1*F3 -> 19603.425 | I3: General names | J3: 0.5 | K3: =N1*J3 -> 9198.2085 | L3: Specific | M3: 0.5 | N3: =N1*M3 -> 9198.2085 | P3: General names | Q3: 0.62 | R3: =U1*Q3 -> 8794.4125 | S3: Specific | T3: =SUM(T4:T31) -> 0.38 | U3: =U1*T3 -> 5390.1238 | W3: General names | X3: =SUM(X4:X56) -> 0.3 | Y3: =SUM(Y4:Y56) -> 6493.6439 | Z3: Specific | AA3: =SUM(AA4:AA24) -> 0.7 | AB3: =SUM(AB4:AB24) -> 15151.836 | AD3: General names | AE3: =SUM(AE4:AE56) -> 0.3 | AF3: =SUM(AF4:AF56) -> 3130.6773 | AG3: Specific | AH3: =SUM(AH4:AH24) -> 0.7 | AI3: =SUM(AI4:AI24) -> 7304.9137 | AK3: General names | AL3: =SUM(AL4:AL56) -> 0.5 | AM3: =SUM(AM4:AM56) -> 9544.8997 | AN3: Specific | AO3: =SUM(AO4:AO48) -> 0.5 | AP3: =SUM(AP4:AP48) -> 9544.8997 | AR3: General names | AS3: =SUM(AS4:AS56) -> 0.5 | AT3: =SUM(AT4:AT56) -> 3989.4008 | AU3: Specific | AV3: =SUM(AV4:AV47) -> 0.5 | AW3: =SUM(AW4:AW38) -> 3989.4008
B4: Ada | C4: 0.04 | D4: =$D$3*C4 -> 522.758 | E4: Dami | F4: 0.04 | G4: =$G$3*F4 -> 784.137 | I4: Ada | J4: 0.02 | K4: =$K$3*J4 -> 183.96417 | L4: Amanda | M4: 0.04 | N4: =$N$3*M4 -> 367.92834 | P4: Ada | Q4: 0.01 | R4: =$U$1*Q4 -> 141.84536 | S4: Dami | T4: =38%/28 -> 0.013571429 | U4: =$U$1*T4 -> 192.50442 | W4: Ada | X4: =0.3/53 -> 0.0056603774 | Y4: =AB$1*X4 -> 122.52158 | Z4: Aisha | AA4: =0.7/21 -> 0.033333333 | AB4: =$AB$1*AA4 -> 721.51599 | AD4: Ada | AE4: =30%/53 -> 0.0056603774 | AF4: =$AI$1*AE4 -> 59.069383 | AG4: Aisha | AH4: 0.08 | AI4: =$AI$1*AH4 -> 834.84728 | AK4: Ada | AL4: =50%/53 -> 0.0094339623 | AM4: =$AP$1*AL4 -> 180.09245 | AN4: Aisha | AO4: =50%/45 -> 0.011111111 | AP4: =$AP$1*AO4 -> 212.10888 | AR4: Ada | AS4: =50%/53 -> 0.0094339623 | AT4: =$AW$1*AS4 -> 75.271714 | AU4: Aisha | AV4: =50%/35 -> 0.014285714 | AW4: =$AW$1*AV4 -> 113.98288
B5: Amaka | C5: 0.02 | D5: =$D$3*C5 -> 261.379 | E5: Dayo | F5: 0.04 | G5: =$G$3*F5 -> 784.137 | I5: Amaka | J5: 0.06 | K5: =$K$3*J5 -> 551.89251 | L5: Chichi | M5: 0.05 | N5: =$N$3*M5 -> 459.91042 | P5: Amaka | Q5: 0.01 | R5: =$U$1*Q5 -> 141.84536 | S5: Dayo | T5: =38%/28 -> 0.013571429 | U5: =$U$1*T5 -> 192.50442 | W5: Amaka | X5: =0.3/53 -> 0.0056603774 | Y5: =AB$1*X5 -> 122.52158 | Z5: Amina | AA5: =0.7/21 -> 0.033333333 | AB5: =$AB$1*AA5 -> 721.51599 | AD5: Amaka | AE5: =30%/53 -> 0.0056603774 | AF5: =$AI$1*AE5 -> 59.069383 | AG5: Amina | AH5: 0.03 | AI5: =$AI$1*AH5 -> 313.06773 | AK5: Amaka | AL5: =50%/53 -> 0.0094339623 | AM5: =$AP$1*AL5 -> 180.09245 | AN5: Amanda | AO5: =50%/45 -> 0.011111111 | AP5: =$AP$1*AO5 -> 212.10888 | AR5: Amaka | AS5: =50%/53 -> 0.0094339623 | AT5: =$AW$1*AS5 -> 75.271714 | AU5: Amanda | AV5: =50%/35 -> 0.014285714 | AW5: =$AW$1*AV5 -> 113.98288
B6: Amara | C6: 0.02 | D6: =$D$3*C6 -> 261.379 | E6: Dupe | F6: 0.04 | G6: =$G$3*F6 -> 784.137 | I6: Amara | J6: 0.05 | K6: =$K$3*J6 -> 459.91042 | L6: Ego | M6: 0.02 | N6: =$N$3*M6 -> 183.96417 | P6: Amara | Q6: 0.01 | R6: =$U$1*Q6 -> 141.84536 | S6: Dupe | T6: =38%/28 -> 0.013571429 | U6: =$U$1*T6 -> 192.50442 | W6: Amara | X6: =0.3/53 -> 0.0056603774 | Y6: =AB$1*X6 -> 122.52158 | Z6: Asmau | AA6: =0.7/21 -> 0.033333333 | AB6: =$AB$1*AA6 -> 721.51599 | AD6: Amara | AE6: =30%/53 -> 0.0056603774 | AF6: =$AI$1*AE6 -> 59.069383 | AG6: Asmau | AH6: 0.03 | AI6: =$AI$1*AH6 -> 313.06773 | AK6: Amara | AL6: =50%/53 -> 0.0094339623 | AM6: =$AP$1*AL6 -> 180.09245 | AN6: Amina | AO6: =50%/45 -> 0.011111111 | AP6: =$AP$1*AO6 -> 212.10888 | AR6: Amara | AS6: =50%/53 -> 0.0094339623 | AT6: =$AW$1*AS6 -> 75.271714 | AU6: Amina | AV6: =50%/35 -> 0.014285714 | AW6: =$AW$1*AV6 -> 113.98288
B7: Anita | C7: 0.05 | D7: =$D$3*C7 -> 653.4475 | E7: Iya mi | F7: 0.05 | G7: =$G$3*F7 -> 980.17125 | I7: Anita | J7: 0.01 | K7: =$K$3*J7 -> 91.982085 | L7: Enyi'm | M7: 0.02 | N7: =$N$3*M7 -> 183.96417 | P7: Anita | Q7: 0.011320755 | R7: =$U$1*Q7 -> 160.57966 | S7: Funmi | T7: =38%/28 -> 0.013571429 | U7: =$U$1*T7 -> 192.50442 | W7: Anita | X7: =0.3/53 -> 0.0056603774 | Y7: =AB$1*X7 -> 122.52158 | Z7: Bilikisu | AA7: =0.7/21 -> 0.033333333 | AB7: =$AB$1*AA7 -> 721.51599 | AD7: Anita | AE7: =30%/53 -> 0.0056603774 | AF7: =$AI$1*AE7 -> 59.069383 | AG7: Bilikisu | AH7: 0.05 | AI7: =$AI$1*AH7 -> 521.77955 | AK7: Anita | AL7: =50%/53 -> 0.0094339623 | AM7: =$AP$1*AL7 -> 180.09245 | AN7: Asmau | AO7: =50%/45 -> 0.011111111 | AP7: =$AP$1*AO7 -> 212.10888 | AR7: Anita | AS7: =50%/53 -> 0.0094339623 | AT7: =$AW$1*AS7 -> 75.271714 | AU7: Chichi | AV7: =50%/35 -> 0.014285714 | AW7: =$AW$1*AV7 -> 113.98288
B8: Aunty | C8: 0.03 | D8: =$D$3*C8 -> 392.0685 | E8: Kehinde | F8: 0.04 | G8: =$G$3*F8 -> 784.137 | I8: Aunty | J8: 0.01 | K8: =$K$3*J8 -> 91.982085 | L8: Ify | M8: 0.15 | N8: =$N$3*M8 -> 1379.7313 | P8: Aunty | Q8: 0.011320755 | R8: =$U$1*Q8 -> 160.57966 | S8: Iya mi | T8: =38%/28 -> 0.013571429 | U8: =$U$1*T8 -> 192.50442 | W8: Aunty | X8: =0.3/53 -> 0.0056603774 | Y8: =AB$1*X8 -> 122.52158 | Z8: Fatima | AA8: =0.7/21 -> 0.033333333 | AB8: =$AB$1*AA8 -> 721.51599 | AD8: Aunty | AE8: =30%/53 -> 0.0056603774 | AF8: =$AI$1*AE8 -> 59.069383 | AG8: Fatima | AH8: 0.02 | AI8: =$AI$1*AH8 -> 208.71182 | AK8: Aunty | AL8: =50%/53 -> 0.0094339623 | AM8: =$AP$1*AL8 -> 180.09245 | AN8: Bilikisu | AO8: =50%/45 -> 0.011111111 | AP8: =$AP$1*AO8 -> 212.10888 | AR8: Aunty | AS8: =50%/53 -> 0.0094339623 | AT8: =$AW$1*AS8 -> 75.271714 | AU8: Ego | AV8: =50%/35 -> 0.014285714 | AW8: =$AW$1*AV8 -> 113.98288
B9: Ayo | C9: 0.03 | D9: =$D$3*C9 -> 392.0685 | E9: Kike | F9: 0.04 | G9: =$G$3*F9 -> 784.137 | I9: Ayo | J9: 0.01 | K9: =$K$3*J9 -> 91.982085 | L9: Ije | M9: 0.15 | N9: =$N$3*M9 -> 1379.7313 | P9: Ayo | Q9: 0.025 | R9: =$U$1*Q9 -> 354.61341 | S9: Kehinde | T9: =38%/28 -> 0.013571429 | U9: =$U$1*T9 -> 192.50442 | W9: Ayo | X9: =0.3/53 -> 0.0056603774 | Y9: =AB$1*X9 -> 122.52158 | Z9: Fauzia | AA9: =0.7/21 -> 0.033333333 | AB9: =$AB$1*AA9 -> 721.51599 | AD9: Ayo | AE9: =30%/53 -> 0.0056603774 | AF9: =$AI$1*AE9 -> 59.069383 | AG9: Fauzia | AH9: 0.02 | AI9: =$AI$1*AH9 -> 208.71182 | AK9: Ayo | AL9: =50%/53 -> 0.0094339623 | AM9: =$AP$1*AL9 -> 180.09245 | AN9: Chichi | AO9: =50%/45 -> 0.011111111 | AP9: =$AP$1*AO9 -> 212.10888 | AR9: Ayo | AS9: =50%/53 -> 0.0094339623 | AT9: =$AW$1*AS9 -> 75.271714 | AU9: Ehi | AV9: =50%/35 -> 0.014285714 | AW9: =$AW$1*AV9 -> 113.98288
B10: Babe | C10: 0.03 | D10: =$D$3*C10 -> 392.0685 | E10: Lola | F10: 0.03 | G10: =$G$3*F10 -> 588.10275 | I10: Babe | J10: 0.01 | K10: =$K$3*J10 -> 91.982085 | L10: Mma | M10: 0.05 | N10: =$N$3*M10 -> 459.91042 | P10: Babe | Q10: 0.0232 | R10: =$U$1*Q10 -> 329.08124 | S10: Kemi | T10: =38%/28 -> 0.013571429 | U10: =$U$1*T10 -> 192.50442 | W10: Babe | X10: =0.3/53 -> 0.0056603774 | Y10: =AB$1*X10 -> 122.52158 | Z10: Gwaggo | AA10: =0.7/21 -> 0.033333333 | AB10: =$AB$1*AA10 -> 721.51599 | AD10: Babe | AE10: =30%/53 -> 0.0056603774 | AF10: =$AI$1*AE10 -> 59.069383 | AG10: Gwaggo | AH10: 0.08 | AI10: =$AI$1*AH10 -> 834.84728 | AK10: Babe | AL10: =50%/53 -> 0.0094339623 | AM10: =$AP$1*AL10 -> 180.09245 | AN10: Ego | AO10: =50%/45 -> 0.011111111 | AP10: =$AP$1*AO10 -> 212.10888 | AR10: Babe | AS10: =50%/53 -> 0.0094339623 | AT10: =$AW$1*AS10 -> 75.271714 | AU10: Ekaette | AV10: =50%/35 -> 0.014285714 | AW10: =$AW$1*AV10 -> 113.98288
B11: Beauty | C11: 0.01 | D11: =$D$3*C11 -> 130.6895 | E11: Maami | F11: 0.06 | G11: =$G$3*F11 -> 1176.2055 | I11: Beauty | J11: 0.01 | K11: =$K$3*J11 -> 91.982085 | L11: Nkem | M11: 0.05 | N11: =$N$3*M11 -> 459.91042 | P11: Beauty | Q11: 0.011320755 | R11: =$U$1*Q11 -> 160.57966 | S11: Kike | T11: =38%/28 -> 0.013571429 | U11: =$U$1*T11 -> 192.50442 | W11: Beauty | X11: =0.3/53 -> 0.0056603774 | Y11: =AB$1*X11 -> 122.52158 | Z11: Hadiza | AA11: =0.7/21 -> 0.033333333 | AB11: =$AB$1*AA11 -> 721.51599 | AD11: Beauty | AE11: =30%/53 -> 0.0056603774 | AF11: =$AI$1*AE11 -> 59.069383 | AG11: Hadiza | AH11: 0.01 | AI11: =$AI$1*AH11 -> 104.35591 | AK11: Beauty | AL11: =50%/53 -> 0.0094339623 | AM11: =$AP$1*AL11 -> 180.09245 | AN11: Ehi | AO11: =50%/45 -> 0.011111111 | AP11: =$AP$1*AO11 -> 212.10888 | AR11: Beauty | AS11: =50%/53 -> 0.0094339623 | AT11: =$AW$1*AS11 -> 75.271714 | AU11: Fatima | AV11: =50%/35 -> 0.014285714 | AW11: =$AW$1*AV11 -> 113.98288
B12: Bestie | C12: 0.03 | D12: =$D$3*C12 -> 392.0685 | E12: Mayowa | F12: 0.03 | G12: =$G$3*F12 -> 588.10275 | I12: Bestie | J12: 0.01 | K12: =$K$3*J12 -> 91.982085 | L12: Nnenna | M12: 0.04 | N12: =$N$3*M12 -> 367.92834 | P12: Bestie | Q12: 0.011320755 | R12: =$U$1*Q12 -> 160.57966 | S12: Lola | T12: =38%/28 -> 0.013571429 | U12: =$U$1*T12 -> 192.50442 | W12: Bestie | X12: =0.3/53 -> 0.0056603774 | Y12: =AB$1*X12 -> 122.52158 | Z12: Hajara | AA12: =0.7/21 -> 0.033333333 | AB12: =$AB$1*AA12 -> 721.51599 | AD12: Bestie | AE12: =30%/53 -> 0.0056603774 | AF12: =$AI$1*AE12 -> 59.069383 | AG12: Hajara | AH12: 0.01 | AI12: =$AI$1*AH12 -> 104.35591 | AK12: Bestie | AL12: =50%/53 -> 0.0094339623 | AM12: =$AP$1*AL12 -> 180.09245 | AN12: Ekaette | AO12: =50%/45 -> 0.011111111 | AP12: =$AP$1*AO12 -> 212.10888 | AR12: Bestie | AS12: =50%/53 -> 0.0094339623 | AT12: =$AW$1*AS12 -> 75.271714 | AU12: Fauzia | AV12: =50%/35 -> 0.014285714 | AW12: =$AW$1*AV12 -> 113.98288
B13: Bimbo | C13: 0.02 | D13: =$D$3*C13 -> 261.379 | E13: Moji | F13: 0.04 | G13: =$G$3*F13 -> 784.137 | I13: Bimbo | J13: 0.01 | K13: =$K$3*J13 -> 91.982085 | L13: Nnwannem Nwanyi | M13: 0.05 | N13: =$N$3*M13 -> 459.91042 | P13: Bimbo | Q13: 0.011320755 | R13: =$U$1*Q13 -> 160.57966 | S13: Maami | T13: =38%/28 -> 0.013571429 | U13: =$U$1*T13 -> 192.50442 | W13: Bimbo | X13: =0.3/53 -> 0.0056603774 | Y13: =AB$1*X13 -> 122.52158 | Z13: HajIya mi | AA13: =0.7/21 -> 0.033333333 | AB13: =$AB$1*AA13 -> 721.51599 | AD13: Bimbo | AE13: =30%/53 -> 0.0056603774 | AF13: =$AI$1*AE13 -> 59.069383 | AG13: HajIya mi | AH13: 0.1 | AI13: =$AI$1*AH13 -> 1043.5591 | AK13: Bimbo | AL13: =50%/53 -> 0.0094339623 | AM13: =$AP$1*AL13 -> 180.09245 | AN13: Fatima | AO13: =50%/45 -> 0.011111111 | AP13: =$AP$1*AO13 -> 212.10888 | AR13: Bimbo | AS13: =50%/53 -> 0.0094339623 | AT13: =$AW$1*AS13 -> 75.271714 | AU13: HajIya mi | AV13: =50%/35 -> 0.014285714 | AW13: =$AW$1*AV13 -> 113.98288
B14: Bisi | C14: 0.02 | D14: =$D$3*C14 -> 261.379 | E14: Nike | F14: 0.03 | G14: =$G$3*F14 -> 588.10275 | I14: Bisi | J14: 0.01 | K14: =$K$3*J14 -> 91.982085 | L14: Nwannem | M14: 0.04 | N14: =$N$3*M14 -> 367.92834 | P14: Bisi | Q14: 0.02 | R14: =$U$1*Q14 -> 283.69073 | S14: Mayowa | T14: =38%/28 -> 0.013571429 | U14: =$U$1*T14 -> 192.50442 | W14: Bisi | X14: =0.3/53 -> 0.0056603774 | Y14: =AB$1*X14 -> 122.52158 | Z14: Halima | AA14: =0.7/21 -> 0.033333333 | AB14: =$AB$1*AA14 -> 721.51599 | AD14: Bisi | AE14: =30%/53 -> 0.0056603774 | AF14: =$AI$1*AE14 -> 59.069383 | AG14: Halima | AH14: 0.05 | AI14: =$AI$1*AH14 -> 521.77955 | AK14: Bisi | AL14: =50%/53 -> 0.0094339623 | AM14: =$AP$1*AL14 -> 180.09245 | AN14: Fauzia | AO14: =50%/45 -> 0.011111111 | AP14: =$AP$1*AO14 -> 212.10888 | AR14: Bisi | AS14: =50%/53 -> 0.0094339623 | AT14: =$AW$1*AS14 -> 75.271714 | AU14: Halima | AV14: =50%/35 -> 0.014285714 | AW14: =$AW$1*AV14 -> 113.98288
B15: Blessing | C15: 0.02 | D15: =$D$3*C15 -> 261.379 | E15: Ope | F15: 0.04 | G15: =$G$3*F15 -> 784.137 | I15: Blessing | J15: 0.01 | K15: =$K$3*J15 -> 91.982085 | L15: Oby | M15: 0.04 | N15: =$N$3*M15 -> 367.92834 | P15: Blessing | Q15: 0.011320755 | R15: =$U$1*Q15 -> 160.57966 | S15: Moji | T15: =38%/28 -> 0.013571429 | U15: =$U$1*T15 -> 192.50442 | W15: Blessing | X15: =0.3/53 -> 0.0056603774 | Y15: =AB$1*X15 -> 122.52158 | Z15: Hauwa | AA15: =0.7/21 -> 0.033333333 | AB15: =$AB$1*AA15 -> 721.51599 | AD15: Blessing | AE15: =30%/53 -> 0.0056603774 | AF15: =$AI$1*AE15 -> 59.069383 | AG15: Hauwa | AH15: 0.02 | AI15: =$AI$1*AH15 -> 208.71182 | AK15: Blessing | AL15: =50%/53 -> 0.0094339623 | AM15: =$AP$1*AL15 -> 180.09245 | AN15: Gwaggo | AO15: =50%/45 -> 0.011111111 | AP15: =$AP$1*AO15 -> 212.10888 | AR15: Blessing | AS15: =50%/53 -> 0.0094339623 | AT15: =$AW$1*AS15 -> 75.271714 | AU15: Hauwa | AV15: =50%/35 -> 0.014285714 | AW15: =$AW$1*AV15 -> 113.98288
... B23: Faith | C23: 0.01 | D23: =$D$3*C23 -> 130.6895 | E23: Titi | F23: 0.03 | G23: =$G$3*F23 -> 588.10275 | I23: Faith | J23: 0.01 | K23: =$K$3*J23 -> 91.982085 | L23: Zuby | M23: 0.03 | N23: =$N$3*M23 -> 275.94625 | P23: Faith | Q23: 0.01 | R23: =$U$1*Q23 -> 141.84536 | S23: Taiwo | T23: =38%/28 -> 0.013571429 | U23: =$U$1*T23 -> 192.50442 | W23: Faith | X23: =0.3/53 -> 0.0056603774 | Y23: =AB$1*X23 -> 122.52158 | Z23: Ummi | AA23: =0.7/21 -> 0.033333333 | AB23: =$AB$1*AA23 -> 721.51599 | AD23: Faith | AE23: =30%/53 -> 0.0056603774 | AF23: =$AI$1*AE23 -> 59.069383 | AG23: Ummi | AH23: 0.03 | AI23: =$AI$1*AH23 -> 313.06773 | AK23: Faith | AL23: =50%/53 -> 0.0094339623 | AM23: =$AP$1*AL23 -> 180.09245 | AN23: Ije | AO23: =50%/45 -> 0.011111111 | AP23: =$AP$1*AO23 -> 212.10888 | AR23: Faith | AS23: =50%/53 -> 0.0094339623 | AT23: =$AW$1*AS23 -> 75.271714 | AU23: Mma | AV23: =50%/35 -> 0.014285714 | AW23: =$AW$1*AV23 -> 113.98288
B24: Fine Girl | C24: 0.02 | D24: =$D$3*C24 -> 261.379 | E24: Tolu | F24: 0.02 | G24: =$G$3*F24 -> 392.0685 | I24: Fine Girl | J24: 0.01 | K24: =$K$3*J24 -> 91.982085 | N24: =SUM(N4:N23) -> 9198.2085 | P24: Fine Girl | Q24: 0.011320755 | R24: =$U$1*Q24 -> 160.57966 | S24: Tayo | T24: =38%/28 -> 0.013571429 | U24: =$U$1*T24 -> 192.50442 | W24: Fine Girl | X24: =0.3/53 -> 0.0056603774 | Y24: =AB$1*X24 -> 122.52158 | Z24: Zainab | AA24: =0.7/21 -> 0.033333333 | AB24: =$AB$1*AA24 -> 721.51599 | AD24: Fine Girl | AE24: =30%/53 -> 0.0056603774 | AF24: =$AI$1*AE24 -> 59.069383 | AG24: Zainab | AH24: 0.02 | AI24: =$AI$1*AH24 -> 208.71182 | AK24: Fine Girl | AL24: =50%/53 -> 0.0094339623 | AM24: =$AP$1*AL24 -> 180.09245 | AN24: Jamillah | AO24: =50%/45 -> 0.011111111 | AP24: =$AP$1*AO24 -> 212.10888 | AR24: Fine Girl | AS24: =50%/53 -> 0.0094339623 | AT24: =$AW$1*AS24 -> 75.271714 | AU24: Nana | AV24: =50%/35 -> 0.014285714 | AW24: =$AW$1*AV24 -> 113.98288
B25: Folake | C25: 0.01 | D25: =$D$3*C25 -> 130.6895 | E25: Tomi | F25: 0.03 | G25: =$G$3*F25 -> 588.10275 | I25: Folake | J25: 0.01 | K25: =$K$3*J25 -> 91.982085 | P25: Folake | Q25: 0.01 | R25: =$U$1*Q25 -> 141.84536 | S25: Titi | T25: =38%/28 -> 0.013571429 | U25: =$U$1*T25 -> 192.50442 | W25: Folake | X25: =0.3/53 -> 0.0056603774 | Y25: =AB$1*X25 -> 122.52158 | AD25: Folake | AE25: =30%/53 -> 0.0056603774 | AF25: =$AI$1*AE25 -> 59.069383 | AK25: Folake | AL25: =50%/53 -> 0.0094339623 | AM25: =$AP$1*AL25 -> 180.09245 | AN25: Khadija | AO25: =50%/45 -> 0.011111111 | AP25: =$AP$1*AO25 -> 212.10888 | AR25: Folake | AS25: =50%/53 -> 0.0094339623 | AT25: =$AW$1*AS25 -> 75.271714 | AU25: Nkem | AV25: =50%/35 -> 0.014285714 | AW25: =$AW$1*AV25 -> 113.98288
B26: Funmi | C26: 0.02 | D26: =$D$3*C26 -> 261.379 | E26: Toyin | F26: 0.03 | G26: =$G$3*F26 -> 588.10275 | I26: Funmi | J26: 0.02 | K26: =$K$3*J26 -> 183.96417 | P26: Funmi | Q26: 0.011320755 | R26: =$U$1*Q26 -> 160.57966 | S26: Tolu | T26: =38%/28 -> 0.013571429 | U26: =$U$1*T26 -> 192.50442 | W26: Funmi | X26: =0.3/53 -> 0.0056603774 | Y26: =AB$1*X26 -> 122.52158 | AD26: Funmi | AE26: =30%/53 -> 0.0056603774 | AF26: =$AI$1*AE26 -> 59.069383 | AK26: Funmi | AL26: =50%/53 -> 0.0094339623 | AM26: =$AP$1*AL26 -> 180.09245 | AN26: Maimuna | AO26: =50%/45 -> 0.011111111 | AP26: =$AP$1*AO26 -> 212.10888 | AR26: Funmi | AS26: =50%/53 -> 0.0094339623 | AT26: =$AW$1*AS26 -> 75.271714 | AU26: Nnenna | AV26: =50%/35 -> 0.014285714 | AW26: =$AW$1*AV26 -> 113.98288
B27: Grace | C27: 0.01 | D27: =$D$3*C27 -> 130.6895 | E27: Tutu | F27: 0.03 | G27: =$G$3*F27 -> 588.10275 | I27: Grace | J27: 0.01 | K27: =$K$3*J27 -> 91.982085 | P27: Grace | Q27: 0.011320755 | R27: =$U$1*Q27 -> 160.57966 | S27: Tomi | T27: =38%/28 -> 0.013571429 | U27: =$U$1*T27 -> 192.50442 | W27: Grace | X27: =0.3/53 -> 0.0056603774 | Y27: =AB$1*X27 -> 122.52158 | AD27: Grace | AE27: =30%/53 -> 0.0056603774 | AF27: =$AI$1*AE27 -> 59.069383 | AK27: Grace | AL27: =50%/53 -> 0.0094339623 | AM27: =$AP$1*AL27 -> 180.09245 | AN27: Mama | AO27: =50%/45 -> 0.011111111 | AP27: =$AP$1*AO27 -> 212.10888 | AR27: Grace | AS27: =50%/53 -> 0.0094339623 | AT27: =$AW$1*AS27 -> 75.271714 | AU27: Oge | AV27: =50%/35 -> 0.014285714 | AW27: =$AW$1*AV27 -> 113.98288
B28: Happiness | C28: 0.01 | D28: =$D$3*C28 -> 130.6895 | E28: Wunmi | F28: 0.07 | G28: =$G$3*F28 -> 1372.2398 | I28: Happiness | J28: 0.01 | K28: =$K$3*J28 -> 91.982085 | P28: Happiness | Q28: 0.011320755 | R28: =$U$1*Q28 -> 160.57966 | S28: Toyin | T28: =38%/28 -> 0.013571429 | U28: =$U$1*T28 -> 192.50442 | W28: Happiness | X28: =0.3/53 -> 0.0056603774 | Y28: =AB$1*X28 -> 122.52158 | AD28: Happiness | AE28: =30%/53 -> 0.0056603774 | AF28: =$AI$1*AE28 -> 59.069383 | AK28: Happiness | AL28: =50%/53 -> 0.0094339623 | AM28: =$AP$1*AL28 -> 180.09245 | AN28: Mariam | AO28: =50%/45 -> 0.011111111 | AP28: =$AP$1*AO28 -> 212.10888 | AR28: Happiness | AS28: =50%/53 -> 0.0094339623 | AT28: =$AW$1*AS28 -> 75.271714 | AU28: Onyeka | AV28: =50%/35 -> 0.014285714 | AW28: =$AW$1*AV28 -> 113.98288
B29: Ife | C29: 0.01 | D29: =$D$3*C29 -> 130.6895 | E29: Yemi | F29: 0.07 | G29: =$G$3*F29 -> 1372.2398 | I29: Ife | J29: 0.01 | K29: =$K$3*J29 -> 91.982085 | P29: Ife | Q29: 0.011320755 | R29: =$U$1*Q29 -> 160.57966 | S29: Tutu | T29: =38%/28 -> 0.013571429 | U29: =$U$1*T29 -> 192.50442 | W29: Ife | X29: =0.3/53 -> 0.0056603774 | Y29: =AB$1*X29 -> 122.52158 | AD29: Ife | AE29: =30%/53 -> 0.0056603774 | AF29: =$AI$1*AE29 -> 59.069383 | AK29: Ife | AL29: =50%/53 -> 0.0094339623 | AM29: =$AP$1*AL29 -> 180.09245 | AN29: Mfon | AO29: =50%/45 -> 0.011111111 | AP29: =$AP$1*AO29 -> 212.10888 | AR29: Ife | AS29: =50%/53 -> 0.0094339623 | AT29: =$AW$1*AS29 -> 75.271714 | AU29: Ope | AV29: =50%/35 -> 0.014285714 | AW29: =$AW$1*AV29 -> 113.98288
B30: Ifeoma | C30: 0.01 | D30: =$D$3*C30 -> 130.6895 | I30: Ifeoma | J30: 0.01 | K30: =$K$3*J30 -> 91.982085 | P30: Ifeoma | Q30: 0.011320755 | R30: =$U$1*Q30 -> 160.57966 | S30: Wunmi | T30: =38%/28 -> 0.013571429 | U30: =$U$1*T30 -> 192.50442 | W30: Ifeoma | X30: =0.3/53 -> 0.0056603774 | Y30: =AB$1*X30 -> 122.52158 | AD30: Ifeoma | AE30: =30%/53 -> 0.0056603774 | AF30: =$AI$1*AE30 -> 59.069383 | AK30: Ifeoma | AL30: =50%/53 -> 0.0094339623 | AM30: =$AP$1*AL30 -> 180.09245 | AN30: Mma | AO30: =50%/45 -> 0.011111111 | AP30: =$AP$1*AO30 -> 212.10888 | AR30: Ifeoma | AS30: =50%/53 -> 0.0094339623 | AT30: =$AW$1*AS30 -> 75.271714 | AU30: Ose | AV30: =50%/35 -> 0.014285714 | AW30: =$AW$1*AV30 -> 113.98288
B31: Ijeoma | C31: 0.02 | D31: =$D$3*C31 -> 261.379 | I31: Ijeoma | J31: 0.01 | K31: =$K$3*J31 -> 91.982085 | P31: Ijeoma | Q31: 0.011320755 | R31: =$U$1*Q31 -> 160.57966 | S31: Yemi | T31: =38%/28 -> 0.013571429 | U31: =$U$1*T31 -> 192.50442 | W31: Ijeoma | X31: =0.3/53 -> 0.0056603774 | Y31: =AB$1*X31 -> 122.52158 | AD31: Ijeoma | AE31: =30%/53 -> 0.0056603774 | AF31: =$AI$1*AE31 -> 59.069383 | AK31: Ijeoma | AL31: =50%/53 -> 0.0094339623 | AM31: =$AP$1*AL31 -> 180.09245 | AN31: Nana | AO31: =50%/45 -> 0.011111111 | AP31: =$AP$1*AO31 -> 212.10888 | AR31: Ijeoma | AS31: =50%/53 -> 0.0094339623 | AT31: =$AW$1*AS31 -> 75.271714 | AU31: SafIya mih | AV31: =50%/35 -> 0.014285714 | AW31: =$AW$1*AV31 -> 113.98288
B32: Ivy | C32: 0.02 | D32: =$D$3*C32 -> 261.379 | I32: Ivy | J32: 0.04 | K32: =$K$3*J32 -> 367.92834 | P32: Ivy | Q32: 0.011320755 | R32: =$U$1*Q32 -> 160.57966 | U32: =SUM(U4:U31) -> 5390.1238 | W32: Ivy | X32: =0.3/53 -> 0.0056603774 | Y32: =AB$1*X32 -> 122.52158 | AD32: Ivy | AE32: =30%/53 -> 0.0056603774 | AF32: =$AI$1*AE32 -> 59.069383 | AK32: Ivy | AL32: =50%/53 -> 0.0094339623 | AM32: =$AP$1*AL32 -> 180.09245 | AN32: Nkem | AO32: =50%/45 -> 0.011111111 | AP32: =$AP$1*AO32 -> 212.10888 | AR32: Ivy | AS32: =50%/53 -> 0.0094339623 | AT32: =$AW$1*AS32 -> 75.271714 | AU32: Shade | AV32: =50%/35 -> 0.014285714 | AW32: =$AW$1*AV32 -> 113.98288
B33: Jennifer | C33: 0.02 | D33: =$D$3*C33 -> 261.379 | I33: Jennifer | J33: 0.07 | K33: =$K$3*J33 -> 643.87459 | P33: Jennifer | Q33: 0.011320755 | R33: =$U$1*Q33 -> 160.57966 | W33: Jennifer | X33: =0.3/53 -> 0.0056603774 | Y33: =AB$1*X33 -> 122.52158 | AD33: Jennifer | AE33: =30%/53 -> 0.0056603774 | AF33: =$AI$1*AE33 -> 59.069383 | AK33: Jennifer | AL33: =50%/53 -> 0.0094339623 | AM33: =$AP$1*AL33 -> 180.09245 | AN33: Nnenna | AO33: =50%/45 -> 0.011111111 | AP33: =$AP$1*AO33 -> 212.10888 | AR33: Jennifer | AS33: =50%/53 -> 0.0094339623 | AT33: =$AW$1*AS33 -> 75.271714 | AU33: Tolu | AV33: =50%/35 -> 0.014285714 | AW33: =$AW$1*AV33 -> 113.98288
B34: Jessica | C34: 0.01 | D34: =$D$3*C34 -> 130.6895 | I34: Jessica | J34: 0.04 | K34: =$K$3*J34 -> 367.92834 | P34: Jessica | Q34: 0.01 | R34: =$U$1*Q34 -> 141.84536 | W34: Jessica | X34: =0.3/53 -> 0.0056603774 | Y34: =AB$1*X34 -> 122.52158 | AD34: Jessica | AE34: =30%/53 -> 0.0056603774 | AF34: =$AI$1*AE34 -> 59.069383 | AK34: Jessica | AL34: =50%/53 -> 0.0094339623 | AM34: =$AP$1*AL34 -> 180.09245 | AN34: Oge | AO34: =50%/45 -> 0.011111111 | AP34: =$AP$1*AO34 -> 212.10888 | AR34: Jessica | AS34: =50%/53 -> 0.0094339623 | AT34: =$AW$1*AS34 -> 75.271714 | AU34: Tomi | AV34: =50%/35 -> 0.014285714 | AW34: =$AW$1*AV34 -> 113.98288
B35: Judith | C35: 0.01 | D35: =$D$3*C35 -> 130.6895 | I35: Judith | J35: 0.04 | K35: =$K$3*J35 -> 367.92834 | P35: Judith | Q35: 0.01 | R35: =$U$1*Q35 -> 141.84536 | W35: Judith | X35: =0.3/53 -> 0.0056603774 | Y35: =AB$1*X35 -> 122.52158 | AD35: Judith | AE35: =30%/53 -> 0.0056603774 | AF35: =$AI$1*AE35 -> 59.069383 | AK35: Judith | AL35: =50%/53 -> 0.0094339623 | AM35: =$AP$1*AL35 -> 180.09245 | AN35: Ope | AO35: =50%/45 -> 0.011111111 | AP35: =$AP$1*AO35 -> 212.10888 | AR35: Judith | AS35: =50%/53 -> 0.0094339623 | AT35: =$AW$1*AS35 -> 75.271714 | AU35: Toyin | AV35: =50%/35 -> 0.014285714 | AW35: =$AW$1*AV35 -> 113.98288
B36: Kemi | C36: 0.02 | D36: =$D$3*C36 -> 261.379 | I36: Kemi | J36: 0.04 | K36: =$K$3*J36 -> 367.92834 | P36: Kemi | Q36: 0.011320755 | R36: =$U$1*Q36 -> 160.57966 | W36: Kemi | X36: =0.3/53 -> 0.0056603774 | Y36: =AB$1*X36 -> 122.52158 | AD36: Kemi | AE36: =30%/53 -> 0.0056603774 | AF36: =$AI$1*AE36 -> 59.069383 | AK36: Kemi | AL36: =50%/53 -> 0.0094339623 | AM36: =$AP$1*AL36 -> 180.09245 | AN36: Ose | AO36: =50%/45 -> 0.011111111 | AP36: =$AP$1*AO36 -> 212.10888 | AR36: Kemi | AS36: =50%/53 -> 0.0094339623 | AT36: =$AW$1*AS36 -> 75.271714 | AU36: Uche | AV36: =50%/35 -> 0.014285714 | AW36: =$AW$1*AV36 -> 113.98288
B37: Lizzy | C37: 0.02 | D37: =$D$3*C37 -> 261.379 | I37: Lizzy | J37: 0.02 | K37: =$K$3*J37 -> 183.96417 | P37: Lizzy | Q37: 0.011320755 | R37: =$U$1*Q37 -> 160.57966 | W37: Lizzy | X37: =0.3/53 -> 0.0056603774 | Y37: =AB$1*X37 -> 122.52158 | AD37: Lizzy | AE37: =30%/53 -> 0.0056603774 | AF37: =$AI$1*AE37 -> 59.069383 | AK37: Lizzy | AL37: =50%/53 -> 0.0094339623 | AM37: =$AP$1*AL37 -> 180.09245 | AN37: SafIya mih | AO37: =50%/45 -> 0.011111111 | AP37: =$AP$1*AO37 -> 212.10888 | AR37: Lizzy | AS37: =50%/53 -> 0.0094339623 | AT37: =$AW$1*AS37 -> 75.271714 | AU37: Uduak | AV37: =50%/35 -> 0.014285714 | AW37: =$AW$1*AV37 -> 113.98288
B38: Martha | C38: 0.01 | D38: =$D$3*C38 -> 130.6895 | I38: Martha | J38: 0.05 | K38: =$K$3*J38 -> 459.91042 | P38: Martha | Q38: 0.011320755 | R38: =$U$1*Q38 -> 160.57966 | W38: Martha | X38: =0.3/53 -> 0.0056603774 | Y38: =AB$1*X38 -> 122.52158 | AD38: Martha | AE38: =30%/53 -> 0.0056603774 | AF38: =$AI$1*AE38 -> 59.069383 | AK38: Martha | AL38: =50%/53 -> 0.0094339623 | AM38: =$AP$1*AL38 -> 180.09245 | AN38: Shade | AO38: =50%/45 -> 0.011111111 | AP38: =$AP$1*AO38 -> 212.10888 | AR38: Martha | AS38: =50%/53 -> 0.0094339623 | AT38: =$AW$1*AS38 -> 75.271714 | AU38: Zainab | AV38: =50%/35 -> 0.014285714 | AW38: =$AW$1*AV38 -> 113.98288
B39: Mary | C39: 0.02 | D39: =$D$3*C39 -> 261.379 | I39: Mary | J39: 0.04 | K39: =$K$3*J39 -> 367.92834 | P39: Mary | Q39: 0.011320755 | R39: =$U$1*Q39 -> 160.57966 | W39: Mary | X39: =0.3/53 -> 0.0056603774 | Y39: =AB$1*X39 -> 122.52158 | AD39: Mary | AE39: =30%/53 -> 0.0056603774 | AF39: =$AI$1*AE39 -> 59.069383 | AK39: Mary | AL39: =50%/53 -> 0.0094339623 | AM39: =$AP$1*AL39 -> 180.09245 | AN39: Sister | AO39: =50%/45 -> 0.011111111 | AP39: =$AP$1*AO39 -> 212.10888 | AR39: Mary | AS39: =50%/53 -> 0.0094339623 | AT39: =$AW$1*AS39 -> 75.271714
B40: Mummy | C40: 0.01 | D40: =$D$3*C40 -> 130.6895 | I40: Mummy | J40: 0.01 | K40: =$K$3*J40 -> 91.982085 | P40: Mummy | Q40: 0.011320755 | R40: =$U$1*Q40 -> 160.57966 | W40: Mummy | X40: =0.3/53 -> 0.0056603774 | Y40: =AB$1*X40 -> 122.52158 | AD40: Mummy | AE40: =30%/53 -> 0.0056603774 | AF40: =$AI$1*AE40 -> 59.069383 | AK40: Mummy | AL40: =50%/53 -> 0.0094339623 | AM40: =$AP$1*AL40 -> 180.09245 | AN40: Tolu | AO40: =50%/45 -> 0.011111111 | AP40: =$AP$1*AO40 -> 212.10888 | AR40: Mummy | AS40: =50%/53 -> 0.0094339623 | AT40: =$AW$1*AS40 -> 75.271714
B41: Ngozi | C41: 0.02 | D41: =$D$3*C41 -> 261.379 | I41: Ngozi | J41: 0.03 | K41: =$K$3*J41 -> 275.94625 | P41: Ngozi | Q41: 0.011320755 | R41: =$U$1*Q41 -> 160.57966 | W41: Ngozi | X41: =0.3/53 -> 0.0056603774 | Y41: =AB$1*X41 -> 122.52158 | AD41: Ngozi | AE41: =30%/53 -> 0.0056603774 | AF41: =$AI$1*AE41 -> 59.069383 | AK41: Ngozi | AL41: =50%/53 -> 0.0094339623 | AM41: =$AP$1*AL41 -> 180.09245 | AN41: Tomi | AO41: =50%/45 -> 0.011111111 | AP41: =$AP$1*AO41 -> 212.10888 | AR41: Ngozi | AS41: =50%/53 -> 0.0094339623 | AT41: =$AW$1*AS41 -> 75.271714
B42: Nkechi | C42: 0.01 | D42: =$D$3*C42 -> 130.6895 | I42: Nkechi | J42: 0.03 | K42: =$K$3*J42 -> 275.94625 | P42: Nkechi | Q42: 0.011320755 | R42: =$U$1*Q42 -> 160.57966 | W42: Nkechi | X42: =0.3/53 -> 0.0056603774 | Y42: =AB$1*X42 -> 122.52158 | AD42: Nkechi | AE42: =30%/53 -> 0.0056603774 | AF42: =$AI$1*AE42 -> 59.069383 | AK42: Nkechi | AL42: =50%/53 -> 0.0094339623 | AM42: =$AP$1*AL42 -> 180.09245 | AN42: Toyin | AO42: =50%/45 -> 0.011111111 | AP42: =$AP$1*AO42 -> 212.10888 | AR42: Nkechi | AS42: =50%/53 -> 0.0094339623 | AT42: =$AW$1*AS42 -> 75.271714
B43: Nkiru | C43: 0.01 | D43: =$D$3*C43 -> 130.6895 | I43: Nkiru | J43: 0.04 | K43: =$K$3*J43 -> 367.92834 | P43: Nkiru | Q43: 0.011320755 | R43: =$U$1*Q43 -> 160.57966 | W43: Nkiru | X43: =0.3/53 -> 0.0056603774 | Y43: =AB$1*X43 -> 122.52158 | AD43: Nkiru | AE43: =30%/53 -> 0.0056603774 | AF43: =$AI$1*AE43 -> 59.069383 | AK43: Nkiru | AL43: =50%/53 -> 0.0094339623 | AM43: =$AP$1*AL43 -> 180.09245 | AN43: Uche | AO43: =50%/45 -> 0.011111111 | AP43: =$AP$1*AO43 -> 212.10888 | AR43: Nkiru | AS43: =50%/53 -> 0.0094339623 | AT43: =$AW$1*AS43 -> 75.271714
B44: Nne | C44: 0.01 | D44: =$D$3*C44 -> 130.6895 | I44: Nne | J44: 0.02 | K44: =$K$3*J44 -> 183.96417 | P44: Nne | Q44: 0.011320755 | R44: =$U$1*Q44 -> 160.57966 | W44: Nne | X44: =0.3/53 -> 0.0056603774 | Y44: =AB$1*X44 -> 122.52158 | AD44: Nne | AE44: =30%/53 -> 0.0056603774 | AF44: =$AI$1*AE44 -> 59.069383 | AK44: Nne | AL44: =50%/53 -> 0.0094339623 | AM44: =$AP$1*AL44 -> 180.09245 | AN44: Uduak | AO44: =50%/45 -> 0.011111111 | AP44: =$AP$1*AO44 -> 212.10888 | AR44: Nne | AS44: =50%/53 -> 0.0094339623 | AT44: =$AW$1*AS44 -> 75.271714
B45: Nneoma | C45: 0.01 | D45: =$D$3*C45 -> 130.6895 | I45: Nneoma | J45: 0.01 | K45: =$K$3*J45 -> 91.982085 | P45: Nneoma | Q45: 0.011320755 | R45: =$U$1*Q45 -> 160.57966 | W45: Nneoma | X45: =0.3/53 -> 0.0056603774 | Y45: =AB$1*X45 -> 122.52158 | AD45: Nneoma | AE45: =30%/53 -> 0.0056603774 | AF45: =$AI$1*AE45 -> 59.069383 | AK45: Nneoma | AL45: =50%/53 -> 0.0094339623 | AM45: =$AP$1*AL45 -> 180.09245 | AN45: Ummi | AO45: =50%/45 -> 0.011111111 | AP45: =$AP$1*AO45 -> 212.10888 | AR45: Nneoma | AS45: =50%/53 -> 0.0094339623 | AT45: =$AW$1*AS45 -> 75.271714
B46: Oluchi | C46: 0.02 | D46: =$D$3*C46 -> 261.379 | I46: Oluchi | J46: 0.03 | K46: =$K$3*J46 -> 275.94625 | P46: Oluchi | Q46: 0.01 | R46: =$U$1*Q46 -> 141.84536 | W46: Oluchi | X46: =0.3/53 -> 0.0056603774 | Y46: =AB$1*X46 -> 122.52158 | AD46: Oluchi | AE46: =30%/53 -> 0.0056603774 | AF46: =$AI$1*AE46 -> 59.069383 | AK46: Oluchi | AL46: =50%/53 -> 0.0094339623 | AM46: =$AP$1*AL46 -> 180.09245 | AN46: Zainab | AO46: =50%/45 -> 0.011111111 | AP46: =$AP$1*AO46 -> 212.10888 | AR46: Oluchi | AS46: =50%/53 -> 0.0094339623 | AT46: =$AW$1*AS46 -> 75.271714
B47: Queen | C47: 0.02 | D47: =$D$3*C47 -> 261.379 | I47: Queen | J47: 0.01 | K47: =$K$3*J47 -> 91.982085 | P47: Queen | Q47: 0.01 | R47: =$U$1*Q47 -> 141.84536 | W47: Queen | X47: =0.3/53 -> 0.0056603774 | Y47: =AB$1*X47 -> 122.52158 | AD47: Queen | AE47: =30%/53 -> 0.0056603774 | AF47: =$AI$1*AE47 -> 59.069383 | AK47: Queen | AL47: =50%/53 -> 0.0094339623 | AM47: =$AP$1*AL47 -> 180.09245 | AN47: Zikorah | AO47: =50%/45 -> 0.011111111 | AP47: =$AP$1*AO47 -> 212.10888 | AR47: Queen | AS47: =50%/53 -> 0.0094339623 | AT47: =$AW$1*AS47 -> 75.271714
...

Sheet Sheet1
F1: Amaka | I1: Ayo | L1: Aisha | N1: Aisha | P1: Aisha
F2: Amanda | I2: Bisi | L2: Amina | N2: Amanda | P2: Amanda
F3: Amara | I3: Bola | L3: Asmau | N3: Amina | P3: Amina
F4: Chichi | I4: Dami | L4: Bilikisu | N4: Asmau | P4: Bisi
F5: Ego | I5: Dayo | L5: Fatima | N5: Bilikisu | P5: Chichi
F6: Enyi'm | I6: Dupe | L6: Fauzia | N6: Chichi | P6: Ego
F7: Ify | I7: Folake | L7: Gwaggo | N7: Ego | P7: Ehi
F8: Ije | I8: Funmi | L8: Hadiza | N8: Ehi | P8: Ekaette
F9: Mma | I9: Iya mi | L9: Hajara | N9: Ekaette | P9: Fatima
F10: Nkechi | I10: Kehinde | L10: HajIya mi | N10: Fatima | P10: Fauzia
F11: Nkem | I11: Kemi | L11: Halima | N11: Fauzia | P11: HajIya mi
F12: Nkiru | I12: Kike | L12: Hauwa | N12: Gwaggo | P12: Halima
... F21: Sochi | I21: Ruqqayat | L21: Zainab | N21: Jamillah | P21: Mma
F22: Sommy | I22: Seun | N22: Khadija | P22: Nana
F23: Uche | I23: Shade | N23: Maimuna | P23: Nkem
F24: Zikorah | I24: Shola | N24: Mama | P24: Nkiru
F25: Zuby | I25: Taiwo | N25: Mariam | P25: Nnenna
I26: Tayo | N26: Mfon | P26: Oge
I27: Titi | N27: Mma | P27: Onyeka
I28: Titi | N28: Nana | P28: Ope
I29: Tolu | N29: Nkem | P29: Ose
I30: Tomi | N30: Nnenna | P30: SafIya mih
I31: Toyin | N31: Oge | P31: Shade
I32: Tutu | N32: Ope | P32: Sister
I33: Wunmi | N33: Ose | P33: Tolu
I34: Yemi | N34: SafIya mih | P34: Tomi
I35: Yetunde | N35: Shade | P35: Toyin
N36: Sister | P36: Uche
N37: Tolu | P37: Uduak
N38: Tomi | P38: Zainab
N39: Toyin
N40: Uche
N41: Uduak
N42: Ummi
N43: Zainab
N44: Zikorah

Sheet By Region
A2: q2
B3: Year | C3: Values | J3: Q4 Target | S3: Wkly/Rr | Y3: Wkly/Rr | AE3: Wkly/Rr
B4: 2024/25 Tgt | D4: 2024/25 | J4: ='Revised Volume'!F12 -> 40628 | K4: ='Revised Volume'!G12 -> 37239 | L4: ='Revised Volume'!H12 -> 46536 | M4: =SUM(J4:L4) -> 124403 | O4: PY | P4: 40628 | Q4: 37239 | R4: 46536 | S4: =AVERAGE(SUM(P4:R4)/13) -> 9569.4615 | U4: L3M | V4: 29127 | W4: 41155 | X4: 26448.227 | Y4: =AVERAGE(SUM(V4:X4)/13) -> 7440.7867 | AA4: L08 | AB4: 36554 | AC4: 36390 | AD4: 45568 | AE4: =AVERAGE(SUM(AB4:AD4)/13) -> 9116.3077
A5: Region | B5: Sum of Cs | C5: Sum of NIV | D5: Sum of Cs | E5: Sum of NIV | H5: Region | I5: % Contr. | J5: P10 | K5: P11 | L5: P12 | M5: Q4 | O5: Projection | P5: =($S$4/3)*13 -> 41467.667 | Q5: =($S$4/3)*13 -> 41467.667 | R5: =($S$4/3)*13 -> 41467.667 | S5: =AVERAGE(SUM(P5:R5)/13) -> 9569.4615 | U5: Projection | V5: =($Y$4/3)*13 -> 32243.409 | W5: =($Y$4/3)*13 -> 32243.409 | X5: =($Y$4/3)*13 -> 32243.409 | Y5: =AVERAGE(SUM(V5:X5)/13) -> 7440.7867 | AA5: Projection | AB5: =($AE$4/3)*13 -> 39504 | AC5: =($AE$4/3)*13 -> 39504 | AD5: =($AE$4/3)*13 -> 39504 | AE5: =AVERAGE(SUM(AB5:AD5)/13) -> 9116.3077
A6: Region 1 (Lagos) | B6: 21990.197 | C6: 448042.54 | D6: 26246 | E6: 568743.41 | H6: Region 1 (Lagos) | I6: =D6/$D$12 -> 0.26263334 | J6: =I6*$J$4 -> 10670.267 | K6: =$K$4*I6 -> 9780.2029 | L6: =$L$4*I6 -> 12221.905 | M6: =SUM(J6:L6) -> 32672.375 | O6: 10% Up | P6: =P5*110% -> 45614.433 | Q6: =Q5*103% -> 42711.697 | R6: =R5*120% -> 49761.2 | S6: =AVERAGE(SUM(P6:R6)/13) -> 10622.102 | U6: 10% Up | V6: =V5*110% -> 35467.75 | W6: =W5*110% -> 35467.75 | X6: =X5*110% -> 35467.75 | Y6: =AVERAGE(SUM(V6:X6)/13) -> 8184.8654 | AA6: 10% Up | AB6: =AB5*110% -> 43454.4 | AC6: =AC5*110% -> 43454.4 | AD6: =AD5*110% -> 43454.4 | AE6: =AVERAGE(SUM(AB6:AD6)/13) -> 10027.938
A7: Region 2 (West) | B7: 12362.838 | C7: 251888.47 | D7: 17804 | E7: 383868.73 | H7: Region 2 (West- Benin Exclusive) | I7: =D7/$D$12 -> 0.17815758 | J7: =I7*$J$4 -> 7238.1863 | K7: =$K$4*I7 -> 6634.4103 | L7: =$L$4*I7 -> 8290.7413 | M7: =SUM(J7:L7)-M8 -> 14184.536 | O7: Growth vs PY | P7: =P6-P4 -> 4986.4333 | Q7: =Q6-Q4 -> 5472.6967 | R7: =R6-R4 -> 3225.2 | U7: Growth vs L3M | V7: =V6-V4 -> 6340.7499 | W7: =W6-W4 -> -5687.2501 | X7: =X6-X4 -> 9019.5229 | AA7: Growth vs L08 | AB7: =AB6-AB4 -> 6900.4 | AC7: =AC6-AC4 -> 7064.4 | AD7: =AD6-AD4 -> -2113.6
A8: Region 3 (East) | B8: 14652.267 | C8: 298563.79 | D8: 14778 | E8: 317639.41 | H8: Benin (36% Contr. To West) | I8: 0.36 | J8: =J7*36% -> 2605.7471 | K8: =K7*36% -> 2388.3877 | L8: =L7*36% -> 2984.6669 | M8: =SUM(J8:L8) -> 7978.8017 | O8: % Growth | P8: =(P6/P4)-1 -> 0.12273391 | Q8: =(Q6/Q4)-1 -> 0.14696143 | R8: =(R6/R4)-1 -> 0.069305484 | S8: =(S6/S4)-1 -> 0.11 | U8: % Growth | V8: =(V6/V4)-1 -> 0.2176932 | W8: =(W6/W4)-1 -> -0.13819099 | X8: =(X6/X4)-1 -> 0.34102562 | Y8: =(Y6/Y4)-1 -> 0.1 | AA8: % Growth | AB8: =(AB6/AB4)-1 -> 0.18877277 | AC8: =(AC6/AC4)-1 -> 0.19413026 | AD8: =(AD6/AD4)-1 -> -0.046383427 | AE8: =(AE6/AE4)-1 -> 0.1
A9: Region 4 (North) | B9: 8556.0582 | C9: 174326.67 | D9: 8383 | E9: 182710.48 | H9: Region 3 (East) | I9: =D8/$D$12 -> 0.1478776 | J9: =I9*$J$4 -> 6007.9711 | K9: =$K$4*I9 -> 5506.8139 | L9: =$L$4*I9 -> 6881.632 | M9: =SUM(J9:L9) -> 18396.417
A10: Region 5 (Mid-Belt) | B10: 16928.145 | C10: 344905.52 | D10: 17388 | E10: 374798.66 | H10: Region 4 (North) | I10: =D9/$D$12 -> 0.083885364 | J10: =I10*$J$4 -> 3408.0946 | K10: =$K$4*I10 -> 3123.8071 | L10: =$L$4*I10 -> 3903.6893 | M10: =SUM(J10:L10) -> 10435.591
A11: Region 6 (Modern Trade) | B11: 12388.514 | C11: 252411.52 | D11: 15335 | E11: 347478.84 | H11: Region 5 (Mid-Belt) | I11: =D10/$D$12 -> 0.17399484 | J11: =I11*$J$4 -> 7069.0622 | K11: =$K$4*I11 -> 6479.3937 | L11: =$L$4*I11 -> 8097.0237 | M11: =SUM(J11:L11) -> 21645.48
A12: Grand Total | B12: 86878.021 | C12: 1770138.5 | D12: 99934 | E12: 2175239.5 | H12: Region 6 (Modern Trade) | I12: =D11/$D$12 -> 0.15345128 | J12: =I12*$J$4 -> 6234.4185 | K12: =$K$4*I12 -> 5714.3721 | L12: =$L$4*I12 -> 7141.0087 | M12: =SUM(J12:L12) -> 19089.799
I13: =D12/$D$12 -> 1 | J13: =I13*$J$4 -> 40628 | K13: =$K$4*I13 -> 37239 | L13: =$L$4*I13 -> 46536 | M13: =SUM(J13:L13) -> 124403
B17: 14564.826 | C17: 14564.84 | D17: 18206.163

Sheet By RDC
B3: Region by RDC | C3: Total
B4: Lagos | C4: ='By Region'!M6 -> 32672.375
B5: West (Ex. Benin) | C5: ='By Region'!M7 -> 14184.536
B6: Modern Trade | C6: ='By Region'!M12/3 -> 6363.2664
B7: Ikorodu RDC | C7: =SUM(C4:C6) -> 53220.178
B8: East | C8: ='By Region'!M9 -> 18396.417
B9: Benin | C9: ='By Region'!M8 -> 7978.8017
B10: Modern Trade | C10: ='By Region'!M12/3 -> 6363.2664
B11: Onitsha RDC | C11: =SUM(C8:C10) -> 32738.485
B12: North | C12: ='By Region'!M10 -> 10435.591
B13: Middle-Belt | C13: ='By Region'!M11 -> 21645.48
B14: Modern Trade | C14: ='By Region'!M12/3 -> 6363.2664
B15: Abuja RDC | C15: =SUM(C12:C14) -> 38444.337
C16: =C7+C11+C15 -> 124403

Sheet General and Northern Names 
B2: General names | C2: Hausa names | D2: WEST | E2: East | F2: South
B3: Mummy | C3: Aisha | D3: Tomi | E3: Nnenna | F3: Ose
B4: Aunty | C4: Halima | D4: Toyin | E4: Sister | F4: Ehi
B5: Bestie | C5: Fatima | D5: Tolu | E5: Chichi | F5: Ekaette
B6: Babe | C6: Zainab | D6: Ope | E6: Ngozi | F6: Mfon
B7: Beauty | C7: Ummi | D7: Kemi | E7: Ada | F7: Uduak
B8: Wifey | C8: Hajiya | D8: Bisi | E8: Uche | F8: Idara
B9: Blessing | C9: Amina | D9: Shade | E9: Ify
B10: Cynthia | C10: Nana | D10: Yetunde | E10: Oge
B11: Mary | C11: Gwaggo | D11: Yemi | E11: Amaka
B12: Darling | C12: Mariam | D12: Titi | E12: Nkechi
B13: Fine Girl | C13: Hauwa | D13: Lola | E13: Oluchi
B14: Lizzy | C14: Hajara | D14: Tayo | E14: Nkem
B15: Happiness | C15: Khadija | D15: Iya | E15: Mma
B16: Judith | C16: Mama | D16: Ruqqayat | E16: Ego
B17: Faith | C17: Jamillah | D17: Ayo | E17: Uju
B18: Sweetie | C18: Hadiza | D18: Shola | E18: Amanda
B19: Queen | C19: Asmau | D19: Dayo | E19: Ije
B20: Martha | C20: Bilikisu | D20: Moji | E20: Zikorah
... B23: Jessica | C23: Fauzia | D23: Tutu | E23: Zuby
B24: Grace | D24: Bola | E24: Amara
B25: Ivy | D25: Kike | E25: Oby
B26: Mary | D26: Folake | E26: Sochi
B27: Rachael | D27: Funmi | E27: Sommy
B28: Vicky | D28: Seun | E28: Nwannem
B29: Anita | D29: Kehinde | E29: Nneoma
B30: Nne | D30: Taiwo | E30: Enyi'm
B31: Ada | D31: Titi | E31: Nnwannem Nwanyi
B32: Chioma | D32: Nike
B33: Chidinma | D33: Wunmi
B34: Oluchi | D34: Mayowa
B35: Uju | D35: Ope
B36: Ifeoma | D36: Ore mi
B37: Amaka | D37: Maami
B38: Amara
B39: Ngozi
B40: Nkiru
B41: Nkechi
B42: Ijeoma
B43: Ezinne
...
